<?xml version="1.0"?>
<robot xmlns:xacro="http://ros.org/wiki/xacro">
  <xacro:macro name="onrobot_rg2ft_gazebo" params="prefix">


    <!-- These joints closes the kinematic loop. Since loops are not allowed in URDF, but they are
      allowed in SDF, this is an SDF fragment. -->
      <gazebo>
        <joint name="${prefix}right_inner_knuckle_to_finger_joint" type="revolute">
          <pose> 0.0095 0 0.0165 0 0 0</pose>
          <axis>
            <xyz>0 1 0</xyz>
            <use_parent_model_frame>false</use_parent_model_frame>
          </axis>
          <parent>${prefix}right_inner_knuckle</parent>
          <child>${prefix}right_inner_finger</child>
        </joint>
      </gazebo>
      <gazebo>
        <joint name="${prefix}left_inner_knuckle_to_finger_joint" type="revolute">
          <pose> -0.0095 0 0.0165 0 0 0</pose>
          <axis>
            <xyz>0 1 0</xyz>
            <use_parent_model_frame>false</use_parent_model_frame>
          </axis>
          <parent>${prefix}left_inner_knuckle</parent>
          <child>${prefix}left_inner_finger</child>
        </joint>
      </gazebo>


    <!-- Mimic joint plugin -->
    <gazebo>
      <plugin filename="libroboticsgroup_upatras_gazebo_mimic_joint_plugin.so"
        name="${prefix}mimic_onrobot_rg2ft_0">
        <joint>${prefix}finger_joint</joint>
        <mimicJoint>${prefix}left_outer_knuckle_joint</mimicJoint>
        <multiplier>-1</multiplier>
        <hasPID />
      </plugin>
    </gazebo>

    <!-- Gazebo Link Properties -->
    <xacro:macro name="onrobot_rg2ft_gazebo_link_properties" params="reference color">
      <gazebo reference="${reference}">
        <visual>
          <material>
            <ambient>${color} 1</ambient>
            <diffuse>${color} 1</diffuse>
            <specular>0.1 0.1 0.1 1</specular>
            <emissive>0 0 0 0</emissive>
          </material>
        </visual>
        <kp>1000000.0</kp>
        <kd>1.0</kd>
        <mu1>1.16</mu1>
        <mu2>1.16</mu2>
        <maxVel>0.0</maxVel>
        <minDepth>0.003</minDepth>
      </gazebo>
    </xacro:macro>
    <xacro:onrobot_rg2ft_gazebo_link_properties reference="${prefix}quick_changer"
      color="55 151 207" />
    <xacro:onrobot_rg2ft_gazebo_link_properties reference="${prefix}angle_bracket"
      color="174 176 173" />
    <xacro:onrobot_rg2ft_gazebo_link_properties reference="${prefix}gripper_body"
      color="174 176 173" />
    <xacro:onrobot_rg2ft_gazebo_link_properties reference="${prefix}left_outer_knuckle"
      color="174 176 173" />
    <xacro:onrobot_rg2ft_gazebo_link_properties reference="${prefix}left_inner_knuckle"
      color="174 176 173" />
    <xacro:onrobot_rg2ft_gazebo_link_properties reference="${prefix}left_inner_finger"
      color="174 176 173" />
    <xacro:onrobot_rg2ft_gazebo_link_properties reference="${prefix}right_outer_knuckle"
      color="174 176 173" />
    <xacro:onrobot_rg2ft_gazebo_link_properties reference="${prefix}right_inner_knuckle"
      color="174 176 173" />
    <xacro:onrobot_rg2ft_gazebo_link_properties reference="${prefix}right_inner_finger"
      color="174 176 173" />

    <xacro:macro name="onrobot_rg2ft_gazebo_joint_properties" params="reference">
      <gazebo reference="${reference}">
        <implicitSpringDamper>true</implicitSpringDamper>
      </gazebo>
    </xacro:macro>
    <xacro:onrobot_rg2ft_gazebo_joint_properties reference="${prefix}finger_joint" />
    <xacro:onrobot_rg2ft_gazebo_joint_properties reference="${prefix}left_outer_knuckle_joint" />
    <xacro:onrobot_rg2ft_gazebo_joint_properties reference="${prefix}left_inner_finger_joint" />
    <xacro:onrobot_rg2ft_gazebo_joint_properties reference="${prefix}left_inner_knuckle_joint" />
    <xacro:onrobot_rg2ft_gazebo_joint_properties
      reference="${prefix}left_inner_knuckle_to_finger_joint" />
    <xacro:onrobot_rg2ft_gazebo_joint_properties reference="${prefix}right_inner_finger_joint" />
    <xacro:onrobot_rg2ft_gazebo_joint_properties reference="${prefix}right_inner_knuckle_joint" />
    <xacro:onrobot_rg2ft_gazebo_joint_properties
      reference="${prefix}right_inner_knuckle_to_finger_joint" />


  </xacro:macro>

</robot>