<?xml version="1.0" ?>
<!-- =================================================================================== -->
<!-- |    This document was autogenerated by xacro from /home/ian/catkin_ws/src/OnRobot_RG2-FT_ROS/onrobot_rg2ft_description/urdf/onrobot_rg2ft.xacro | -->
<!-- |    EDITING THIS FILE BY HAND IS NOT RECOMMENDED                                 | -->
<!-- =================================================================================== -->
<robot name="onrobot_rg2ft">
    <transmission name="finger_joint_trans">
        <type>transmission_interface/SimpleTransmission</type>
        <joint name="finger_joint">
            <hardwareInterface>hardware_interface/EffortJointInterface</hardwareInterface>
        </joint>
        <actuator name="finger_joint_motor">
            <mechanicalReduction>1</mechanicalReduction>
            <hardwareInterface>hardware_interface/EffortJointInterface</hardwareInterface>
        </actuator>
    </transmission>
    <!-- Mimic joint plugin -->
    <gazebo>
        <plugin filename="libroboticsgroup_upatras_gazebo_mimic_joint_plugin.so" name="mimic_onrobot_rg2ft_0">
            <joint>finger_joint</joint>
            <mimicJoint>right_outer_knuckle_joint</mimicJoint>
            <multiplier>1</multiplier>
            <hasPID />
        </plugin>
        <plugin name="gazebo_ros_control">
            <robotNamespace>/</robotNamespace>
        </plugin>
    </gazebo>
    <gazebo reference="quick_changer">
        <material>Gazebo/Blue</material>
        <kp>1000000.0</kp>
        <kd>1.0</kd>
        <mu1>1.16</mu1>
        <mu2>1.16</mu2>
        <maxVel>0.0</maxVel>
        <minDepth>0.003</minDepth>
    </gazebo>
    <gazebo reference="angle_bracket">
        <material>Gazebo/Grey</material>
        <kp>1000000.0</kp>
        <kd>1.0</kd>
        <mu1>1.16</mu1>
        <mu2>1.16</mu2>
        <maxVel>0.0</maxVel>
        <minDepth>0.003</minDepth>
    </gazebo>
    <gazebo reference="gripper_body">
        <material>Gazebo/Grey</material>
        <kp>1000000.0</kp>
        <kd>1.0</kd>
        <mu1>1.16</mu1>
        <mu2>1.16</mu2>
        <maxVel>0.0</maxVel>
        <minDepth>0.003</minDepth>
    </gazebo>
    <gazebo reference="left_outer_knuckle">
        <material>Gazebo/Grey</material>
        <kp>1000000.0</kp>
        <kd>1.0</kd>
        <mu1>1.16</mu1>
        <mu2>1.16</mu2>
        <maxVel>0.0</maxVel>
        <minDepth>0.003</minDepth>
    </gazebo>
    <gazebo reference="left_inner_knuckle">
        <material>Gazebo/Grey</material>
        <kp>1000000.0</kp>
        <kd>1.0</kd>
        <mu1>1.16</mu1>
        <mu2>1.16</mu2>
        <maxVel>0.0</maxVel>
        <minDepth>0.003</minDepth>
    </gazebo>
    <gazebo reference="left_inner_finger">
        <material>Gazebo/Grey</material>
        <kp>1000000.0</kp>
        <kd>1.0</kd>
        <mu1>1.16</mu1>
        <mu2>1.16</mu2>
        <maxVel>0.0</maxVel>
        <minDepth>0.003</minDepth>
    </gazebo>
    <gazebo reference="right_outer_knuckle">
        <material>Gazebo/Grey</material>
        <kp>1000000.0</kp>
        <kd>1.0</kd>
        <mu1>1.16</mu1>
        <mu2>1.16</mu2>
        <maxVel>0.0</maxVel>
        <minDepth>0.003</minDepth>
    </gazebo>
    <gazebo reference="right_inner_knuckle">
        <material>Gazebo/Grey</material>
        <kp>1000000.0</kp>
        <kd>1.0</kd>
        <mu1>1.16</mu1>
        <mu2>1.16</mu2>
        <maxVel>0.0</maxVel>
        <minDepth>0.003</minDepth>
    </gazebo>
    <gazebo reference="right_inner_finger">
        <material>Gazebo/Grey</material>
        <kp>1000000.0</kp>
        <kd>1.0</kd>
        <mu1>1.16</mu1>
        <mu2>1.16</mu2>
        <maxVel>0.0</maxVel>
        <minDepth>0.003</minDepth>
    </gazebo>
    <gazebo reference="finger_joint">
        <implicitSpringDamper>true</implicitSpringDamper>
    </gazebo>
    <gazebo reference="left_outer_knuckle_joint">
        <implicitSpringDamper>true</implicitSpringDamper>
    </gazebo>
    <gazebo reference="left_inner_finger_joint">
        <implicitSpringDamper>true</implicitSpringDamper>
    </gazebo>
    <gazebo reference="left_inner_knuckle_joint">
        <implicitSpringDamper>true</implicitSpringDamper>
    </gazebo>
    <gazebo reference="left_inner_knuckle_to_finger_joint">
        <implicitSpringDamper>true</implicitSpringDamper>
    </gazebo>
    <gazebo reference="right_inner_finger_joint">
        <implicitSpringDamper>true</implicitSpringDamper>
    </gazebo>
    <gazebo reference="right_inner_knuckle_joint">
        <implicitSpringDamper>true</implicitSpringDamper>
    </gazebo>
    <gazebo reference="right_inner_knuckle_to_finger_joint">
        <implicitSpringDamper>true</implicitSpringDamper>
    </gazebo>
    <material name="silver">
        <color rgba="0.700 0.700 0.700 1.000" />
    </material>
    <material name="blue">
        <color rgba="0.21568627450980393 0.592156862745098 0.8117647058823529 1.000" />
    </material>
    <link name="quick_changer">
        <inertial>
            <origin rpy="0 0 0" xyz="0.0014673787228634701 -0.0007395056519161622 0.00391087859435364" />
            <mass value="0.05802030412577654" />
            <inertia ixx="2e-05" ixy="-0.0" ixz="-0.0" iyy="2.7e-05" iyz="0.0" izz="4.5e-05" />
        </inertial>
        <visual>
            <origin rpy="0 0 0" xyz="0 0 0" />
            <geometry>
                <mesh filename="package://onrobot_rg2ft_description/meshes/visual/quick_changer.stl" scale="0.001 0.001 0.001" />
            </geometry>
            <material name="blue" />
        </visual>
        <collision>
            <origin rpy="0 0 0" xyz="0 0 0" />
            <geometry>
                <mesh filename="package://onrobot_rg2ft_description/meshes/collision/quick_changer.stl" scale="0.001 0.001 0.001" />
            </geometry>
        </collision>
    </link>
    <link name="gripper_body">
        <inertial>
            <origin rpy="0 0 0" xyz="0.0272971231150397 -0.002438088956580745 0.035297715994502724" />
            <mass value="0.5707794664902835" />
            <inertia ixx="0.000622" ixy="3e-06" ixz="0.0" iyy="0.000662" iyz="1.8e-05" izz="0.000226" />
        </inertial>
        <visual>
            <origin rpy="0 0 0" xyz="0.02705 -0.0 -0.047" />
            <geometry>
                <mesh filename="package://onrobot_rg2ft_description/meshes/visual/gripper_body.stl" scale="0.001 0.001 0.001" />
            </geometry>
            <material name="silver" />
        </visual>
        <collision>
            <origin rpy="0 0 0" xyz="0.02705 -0.0 -0.047" />
            <geometry>
                <mesh filename="package://onrobot_rg2ft_description/meshes/collision/gripper_body.stl" scale="0.001 0.001 0.001" />
            </geometry>
        </collision>
    </link>
    <link name="angle_bracket">
        <inertial>
            <origin rpy="0 0 0" xyz="-0.00023577776357350244 0.0006406606087327927 0.01993861451986476" />
            <mass value="0.19757034519537245" />
            <inertia ixx="9.8e-05" ixy="-0.0" ixz="-1e-06" iyy="0.000145" iyz="2e-06" izz="0.000155" />
        </inertial>
        <visual>
            <origin rpy="0 0 0" xyz="-0.0 -0.0 -0.00255" />
            <geometry>
                <mesh filename="package://onrobot_rg2ft_description/meshes/visual/angle_bracket.stl" scale="0.001 0.001 0.001" />
            </geometry>
            <material name="silver" />
        </visual>
        <collision>
            <origin rpy="0 0 0" xyz="-0.0 -0.0 -0.00255" />
            <geometry>
                <mesh filename="package://onrobot_rg2ft_description/meshes/collision/angle_bracket.stl" scale="0.001 0.001 0.001" />
            </geometry>
        </collision>
    </link>
    <link name="left_inner_knuckle">
        <inertial>
            <origin rpy="0 0 0" xyz="0.01762916513992015 0.010471874847992522 0.017068183318320468" />
            <mass value="0.024337519273275633" />
            <inertia ixx="5e-06" ixy="-0.0" ixz="-3e-06" iyy="7e-06" iyz="-0.0" izz="5e-06" />
        </inertial>
        <visual>
            <origin rpy="0 0 0" xyz="-0.0075 0.009367 -0.139397" />
            <geometry>
                <mesh filename="package://onrobot_rg2ft_description/meshes/visual/left_inner_knuckle.stl" scale="0.001 0.001 0.001" />
            </geometry>
            <material name="silver" />
        </visual>
        <collision>
            <origin rpy="0 0 0" xyz="-0.0075 0.009367 -0.139397" />
            <geometry>
                <mesh filename="package://onrobot_rg2ft_description/meshes/collision/left_inner_knuckle.stl" scale="0.001 0.001 0.001" />
            </geometry>
        </collision>
    </link>
    <link name="right_outer_knuckle">
        <inertial>
            <origin rpy="0 0 0" xyz="-0.012312223780380358 0.010369678145266329 0.010203759185649544" />
            <mass value="0.041583686281793396" />
            <inertia ixx="1e-05" ixy="0.0" ixz="7e-06" iyy="1.6e-05" iyz="-0.0" izz="1e-05" />
        </inertial>
        <visual>
            <origin rpy="0 0 0" xyz="0.017 0.009534 -0.122898" />
            <geometry>
                <mesh filename="package://onrobot_rg2ft_description/meshes/visual/right_outer_knuckle.stl" scale="0.001 0.001 0.001" />
            </geometry>
            <material name="silver" />
        </visual>
        <collision>
            <origin rpy="0 0 0" xyz="0.017 0.009534 -0.122898" />
            <geometry>
                <mesh filename="package://onrobot_rg2ft_description/meshes/collision/right_outer_knuckle.stl" scale="0.001 0.001 0.001" />
            </geometry>
        </collision>
    </link>
    <link name="left_outer_knuckle">
        <inertial>
            <origin rpy="0 0 0" xyz="0.01231204747983699 0.010369678145260136 0.01020375918419171" />
            <mass value="0.04158368628179342" />
            <inertia ixx="1e-05" ixy="-0.0" ixz="-7e-06" iyy="1.6e-05" iyz="-0.0" izz="1e-05" />
        </inertial>
        <visual>
            <origin rpy="0 0 0" xyz="-0.017 0.009534 -0.122898" />
            <geometry>
                <mesh filename="package://onrobot_rg2ft_description/meshes/visual/left_outer_knuckle.stl" scale="0.001 0.001 0.001" />
            </geometry>
            <material name="silver" />
        </visual>
        <collision>
            <origin rpy="0 0 0" xyz="-0.017 0.009534 -0.122898" />
            <geometry>
                <mesh filename="package://onrobot_rg2ft_description/meshes/collision/left_outer_knuckle.stl" scale="0.001 0.001 0.001" />
            </geometry>
        </collision>
    </link>
    <link name="left_inner_finger">
        <inertial>
            <origin rpy="0 0 0" xyz="-0.009341477027312806 0.006108535220686467 0.03133683897712786" />
            <mass value="0.03203868115594587" />
            <inertia ixx="9e-06" ixy="0.0" ixz="2e-06" iyy="9e-06" iyz="-0.0" izz="2e-06" />
        </inertial>
        <visual>
            <origin rpy="0 0 0" xyz="-0.056748 0.00475 -0.160866" />
            <geometry>
                <mesh filename="package://onrobot_rg2ft_description/meshes/visual/left_inner_finger.stl" scale="0.001 0.001 0.001" />
            </geometry>
            <material name="silver" />
        </visual>
        <collision>
            <origin rpy="0 0 0" xyz="-0.056748 0.00475 -0.160866" />
            <geometry>
                <mesh filename="package://onrobot_rg2ft_description/meshes/collision/left_inner_finger.stl" scale="0.001 0.001 0.001" />
            </geometry>
        </collision>
    </link>
    <link name="right_inner_finger">
        <inertial>
            <origin rpy="0 0 0" xyz="0.009341300963273541 0.006108535097342211 0.03133683984830843" />
            <mass value="0.032038680057528524" />
            <inertia ixx="9e-06" ixy="-0.0" ixz="-2e-06" iyy="9e-06" iyz="-0.0" izz="2e-06" />
        </inertial>
        <visual>
            <origin rpy="0 0 0" xyz="0.056748 0.00475 -0.160866" />
            <geometry>
                <mesh filename="package://onrobot_rg2ft_description/meshes/visual/right_inner_finger.stl" scale="0.001 0.001 0.001" />
            </geometry>
            <material name="silver" />
        </visual>
        <collision>
            <origin rpy="0 0 0" xyz="0.056748 0.00475 -0.160866" />
            <geometry>
                <mesh filename="package://onrobot_rg2ft_description/meshes/collision/right_inner_finger.stl" scale="0.001 0.001 0.001" />
            </geometry>
        </collision>
    </link>
    <link name="right_inner_knuckle">
        <inertial>
            <origin rpy="0 0 0" xyz="-0.017629341439301484 0.010471874848001397 0.017068183319570135" />
            <mass value="0.024337519273275623" />
            <inertia ixx="5e-06" ixy="0.0" ixz="3e-06" iyy="7e-06" iyz="-0.0" izz="5e-06" />
        </inertial>
        <visual>
            <origin rpy="0 0 0" xyz="0.0075 0.009367 -0.139397" />
            <geometry>
                <mesh filename="package://onrobot_rg2ft_description/meshes/visual/right_inner_knuckle.stl" scale="0.001 0.001 0.001" />
            </geometry>
            <material name="silver" />
        </visual>
        <collision>
            <origin rpy="0 0 0" xyz="0.0075 0.009367 -0.139397" />
            <geometry>
                <mesh filename="package://onrobot_rg2ft_description/meshes/collision/right_inner_knuckle.stl" scale="0.001 0.001 0.001" />
            </geometry>
        </collision>
    </link>
    <joint name="quick_changer_joint" type="fixed">
        <parent link="world" />
        <child link="quick_changer" />
        <origin rpy="0 0 0" xyz="0 0 0.1" />
    </joint>
    <joint name="gripper_body_joint" type="fixed">
        <origin rpy="0 0 0" xyz="-0.02705 0.0 0.04445" />
        <parent link="angle_bracket" />
        <child link="gripper_body" />
    </joint>
    <joint name="angle_bracket_joint" type="fixed">
        <origin rpy="0 0 0" xyz="0.0 0.0 0.00255" />
        <parent link="quick_changer" />
        <child link="angle_bracket" />
    </joint>
    <joint name="left_inner_knuckle_joint" type="revolute">
        <origin rpy="0 0.4153883619746504 0" xyz="0.03455 -0.009367 0.092397" />
        <parent link="gripper_body" />
        <child link="left_inner_knuckle" />
        <axis xyz="-0.0 0.999949 -0.010122" />
        <limit effort="50.0" lower="-0.01" upper="1.2" velocity="2.0" />
        <mimic joint="finger_joint" multiplier="-1" offset="0" />
    </joint>
    <joint name="finger_joint" type="revolute">
        <origin rpy="0 -0.4153883619746504 0" xyz="0.01005 -0.009534 0.075898" />
        <parent link="gripper_body" />
        <child link="right_outer_knuckle" />
        <axis xyz="-0.0 0.999949 -0.010122" />
        <limit effort="50.0" lower="0" upper="1.19" velocity="2.0" />
    </joint>
    <joint name="left_outer_knuckle_joint" type="revolute">
        <origin rpy="0 0.4153883619746504 0" xyz="0.04405 -0.009534 0.075898" />
        <parent link="gripper_body" />
        <child link="left_outer_knuckle" />
        <axis xyz="-0.0 0.999949 -0.010122" />
        <limit effort="50.0" lower="-0.01" upper="1.2" velocity="2.0" />
        <mimic joint="finger_joint" multiplier="-1" offset="0" />
    </joint>
    <joint name="left_inner_finger_joint" type="revolute">
        <origin rpy="0 -0.4153883619746504 0" xyz="0.039748 0.004784 0.037968" />
        <parent link="left_outer_knuckle" />
        <child link="left_inner_finger" />
        <axis xyz="0.0 -0.999949 0.010122" />
        <limit effort="50.0" lower="-0.01" upper="1.2" velocity="2.0" />
        <mimic joint="finger_joint" multiplier="-1" offset="0" />
    </joint>
    <joint name="right_inner_finger_joint" type="revolute">
        <origin rpy="0 0.4153883619746504 0" xyz="-0.039748 0.004784 0.037968" />
        <parent link="right_outer_knuckle" />
        <child link="right_inner_finger" />
        <axis xyz="0.0 0.999949 -0.010122" />
        <limit effort="50.0" lower="-0.01" upper="1.2" velocity="2.0" />
        <mimic joint="finger_joint" multiplier="-1" offset="0" />
    </joint>
    <joint name="right_inner_knuckle_joint" type="revolute">
        <origin rpy="0 -0.4153883619746504 0" xyz="0.01955 -0.009367 0.092397" />
        <parent link="gripper_body" />
        <child link="right_inner_knuckle" />
        <axis xyz="-0.0 0.999949 -0.010122" />
        <limit effort="50.0" lower="-0.01" upper="1.2" velocity="2.0" />
        <mimic joint="finger_joint" multiplier="1" offset="0" />
    </joint>
    <link name="world" />
    <gazebo>
        <plugin filename="libgazebo_ros_control.so" name="ros_control" />
    </gazebo>
    <transmission name="trans_left_inner_knuckle_joint">
        <type>transmission_interface/SimpleTransmission</type>
        <joint name="left_inner_knuckle_joint">
            <hardwareInterface>hardware_interface/EffortJointInterface</hardwareInterface>
        </joint>
        <actuator name="left_inner_knuckle_joint_motor">
            <hardwareInterface>hardware_interface/EffortJointInterface</hardwareInterface>
            <mechanicalReduction>1</mechanicalReduction>
        </actuator>
    </transmission>
    <transmission name="trans_left_outer_knuckle_joint">
        <type>transmission_interface/SimpleTransmission</type>
        <joint name="left_outer_knuckle_joint">
            <hardwareInterface>hardware_interface/EffortJointInterface</hardwareInterface>
        </joint>
        <actuator name="left_outer_knuckle_joint_motor">
            <hardwareInterface>hardware_interface/EffortJointInterface</hardwareInterface>
            <mechanicalReduction>1</mechanicalReduction>
        </actuator>
    </transmission>
    <transmission name="trans_left_inner_finger_joint">
        <type>transmission_interface/SimpleTransmission</type>
        <joint name="left_inner_finger_joint">
            <hardwareInterface>hardware_interface/EffortJointInterface</hardwareInterface>
        </joint>
        <actuator name="left_inner_finger_joint_motor">
            <hardwareInterface>hardware_interface/EffortJointInterface</hardwareInterface>
            <mechanicalReduction>1</mechanicalReduction>
        </actuator>
    </transmission>
    <transmission name="trans_right_inner_finger_joint">
        <type>transmission_interface/SimpleTransmission</type>
        <joint name="right_inner_finger_joint">
            <hardwareInterface>hardware_interface/EffortJointInterface</hardwareInterface>
        </joint>
        <actuator name="right_inner_finger_joint_motor">
            <hardwareInterface>hardware_interface/EffortJointInterface</hardwareInterface>
            <mechanicalReduction>1</mechanicalReduction>
        </actuator>
    </transmission>
    <transmission name="trans_right_inner_knuckle_joint">
        <type>transmission_interface/SimpleTransmission</type>
        <joint name="right_inner_knuckle_joint">
            <hardwareInterface>hardware_interface/EffortJointInterface</hardwareInterface>
        </joint>
        <actuator name="right_inner_knuckle_joint_motor">
            <hardwareInterface>hardware_interface/EffortJointInterface</hardwareInterface>
            <mechanicalReduction>1</mechanicalReduction>
        </actuator>
    </transmission>
</robot>

